<?xml version="1.0" ?>
<!-- =================================================================================== -->
<!-- |    This document was autogenerated by xacro from TwoJointRobot_woCyl.xacro      | -->
<!-- |    EDITING THIS FILE BY HAND IS NOT RECOMMENDED                                 | -->
<!-- =================================================================================== -->
<robot name="TwoJointRobot" xmlns:xacro="http://www.ros.org/wiki/xacro">
  <material name="blue">
    <color rgba="0 0 0.8 1"/>
  </material>
  <material name="white">
    <color rgba="1 1 1 1"/>
  </material>
  <link name="base_link">
    <visual>
      <geometry>
        <cylinder length="0.05" radius="0.075"/>
      </geometry>
      <origin rpy="0 0 0" xyz="0 0 0.025"/>
    </visual>
    <collision>
      <geometry>
        <cylinder length="0.05" radius="0.075"/>
      </geometry>
      <origin rpy="0 0 0" xyz="0 0 0.025"/>
    </collision>
    <inertial>
      <mass value="0.2"/>
      <inertia ixx="0.00045787" ixy="0.0" ixz="0.0" iyy="0.00045787" iyz="0.0" izz="0.0008112"/>
    </inertial>
  </link>
  <link name="link_1">
    <visual>
      <geometry>
        <box size="1.0 0.1 0.05"/>
      </geometry>
      <origin rpy="0 0 0" xyz="0 0 0"/>
      <material name="blue"/>
    </visual>
    <collision>
      <geometry>
        <box size="1.0 0.1 0.05"/>
      </geometry>
      <origin rpy="0 0 0" xyz="0 0 0"/>
    </collision>
    <inertial>
      <mass value="0.5"/>
      <inertia ixx="0.0005461667" ixy="0.0" ixz="0." iyy="0.0419461667" iyz="0" izz="0.042267"/>
    </inertial>
  </link>
  
  <joint name="joint_1" type="revolute">
    <axis xyz="0 0 1"/>
    <limit effort="10000" lower="-3.14" upper="3.14" velocity="5"/>
    <dynamics damping="0" friction="0"/>
    <origin rpy="0 0 0" xyz="0 0 0"/>
    <parent link="base_link"/>
    <child link="link_1"/>
  </joint>
  
</robot>

